Workbook

Sheet Supplier_Dashboard
A1: Zomorod Supplier Intelligence — Dashboard
A3: Total suppliers (with email) | B3: =COUNTIF(Supplier_Intelligence!$I$2:$I$3001,"*?@*.*")
A4: Total LOW risk | B4: =COUNTIF(Supplier_Intelligence!$R$2:$R$3001,"LOW")
A5: Total MED risk | B5: =COUNTIF(Supplier_Intelligence!$R$2:$R$3001,"MED")
A6: Total HIGH risk | B6: =COUNTIF(Supplier_Intelligence!$R$2:$R$3001,"HIGH")
A8: By Country (email-verified) | D8: By Category (email-verified)
A9: Country | B9: Suppliers | D9: Primary Category | E9: Suppliers
A10: Malaysia | B10: =COUNTIFS(Supplier_Intelligence!$C$2:$C$3001,A10,Supplier_Intelligence!$I$2:$I$3001,"*?@*.*") | D10: Wound Care | E10: =COUNTIFS(Supplier_Intelligence!$E$2:$E$3001,D10,Supplier_Intelligence!$I$2:$I$3001,"*?@*.*")
A11: Turkey | B11: =COUNTIFS(Supplier_Intelligence!$C$2:$C$3001,A11,Supplier_Intelligence!$I$2:$I$3001,"*?@*.*") | D11: Syringes & Needles | E11: =COUNTIFS(Supplier_Intelligence!$E$2:$E$3001,D11,Supplier_Intelligence!$I$2:$I$3001,"*?@*.*")
A12: China | B12: =COUNTIFS(Supplier_Intelligence!$C$2:$C$3001,A12,Supplier_Intelligence!$I$2:$I$3001,"*?@*.*") | D12: IV Cannulas | E12: =COUNTIFS(Supplier_Intelligence!$E$2:$E$3001,D12,Supplier_Intelligence!$I$2:$I$3001,"*?@*.*")
A13: Egypt | B13: =COUNTIFS(Supplier_Intelligence!$C$2:$C$3001,A13,Supplier_Intelligence!$I$2:$I$3001,"*?@*.*") | D13: IV Infusion Sets | E13: =COUNTIFS(Supplier_Intelligence!$E$2:$E$3001,D13,Supplier_Intelligence!$I$2:$I$3001,"*?@*.*")
A14: Germany | B14: =COUNTIFS(Supplier_Intelligence!$C$2:$C$3001,A14,Supplier_Intelligence!$I$2:$I$3001,"*?@*.*") | D14: Catheters | E14: =COUNTIFS(Supplier_Intelligence!$E$2:$E$3001,D14,Supplier_Intelligence!$I$2:$I$3001,"*?@*.*")
A15: France | B15: =COUNTIFS(Supplier_Intelligence!$C$2:$C$3001,A15,Supplier_Intelligence!$I$2:$I$3001,"*?@*.*") | D15: Gloves | E15: =COUNTIFS(Supplier_Intelligence!$E$2:$E$3001,D15,Supplier_Intelligence!$I$2:$I$3001,"*?@*.*")
A16: Italy | B16: =COUNTIFS(Supplier_Intelligence!$C$2:$C$3001,A16,Supplier_Intelligence!$I$2:$I$3001,"*?@*.*") | D16: PPE | E16: =COUNTIFS(Supplier_Intelligence!$E$2:$E$3001,D16,Supplier_Intelligence!$I$2:$I$3001,"*?@*.*")
A17: Spain | B17: =COUNTIFS(Supplier_Intelligence!$C$2:$C$3001,A17,Supplier_Intelligence!$I$2:$I$3001,"*?@*.*") | D17: Gauze & Bandages | E17: =COUNTIFS(Supplier_Intelligence!$E$2:$E$3001,D17,Supplier_Intelligence!$I$2:$I$3001,"*?@*.*")
A18: United Kingdom | B18: =COUNTIFS(Supplier_Intelligence!$C$2:$C$3001,A18,Supplier_Intelligence!$I$2:$I$3001,"*?@*.*") | D18: Disinfectants | E18: =COUNTIFS(Supplier_Intelligence!$E$2:$E$3001,D18,Supplier_Intelligence!$I$2:$I$3001,"*?@*.*")
D19: Lab Consumables | E19: =COUNTIFS(Supplier_Intelligence!$E$2:$E$3001,D19,Supplier_Intelligence!$I$2:$I$3001,"*?@*.*")

Sheet RFQ_Batch_Generator
A1: RFQ Batch Generator (LOW/MED recommended)
J2: Categories | K2: Countries | L2: RiskLevels
A3: Primary Category (optional) | J3: Wound Care | K3: Malaysia | L3: LOW
A4: Country (optional) | J4: Syringes & Needles | K4: Turkey | L4: MED
A5: Max Risk Level | B5: MED | J5: IV Cannulas | K5: China | L5: HIGH
A6: Batch Size | B6: 100 | J6: IV Infusion Sets | K6: Egypt
A7: Batch # | B7: 1 | J7: Catheters | K7: Germany
J8: Gloves | K8: France
A9: Company | B9: Email(s) | C9: Country | D9: Primary_Category | E9: Risk_Level | F9: Evidence_URL | J9: PPE | K9: Italy
A10: =LET(cat,$B$3,cty,$B$4,maxRisk,$B$5,batchSize,$B$6,batchNum,$B$7,tbl,Supplier_Intelligence!$A$2:$U$3001,co,INDEX(tbl,,2),em,INDEX(tbl,,9),country,INDEX(tbl,,3),pcat,INDEX(tbl,,5),risk,INDEX(tbl,,18),ev,INDEX(tbl,,15),isRisk,IF(maxRisk="LOW",risk="LOW",IF(maxRisk="MED",(risk="LOW")+(risk="MED"),1)),isCat,IF(cat="",1,pcat=cat),isCty,IF(cty="",1,country=cty),mask,(co<>"")*(em<>"")*isRisk*isCat*isCty,filtered,FILTER(HSTACK(co,em,country,pcat,risk,ev),mask,""),start,(batchNum-1)*batchSize+1,TAKE(DROP(filtered,start-1),batchSize)) | J10: Gauze & Bandages | K10: Spain
J11: Disinfectants | K11: United Kingdom
J12: Lab Consumables

Sheet README
A1: Zomorod Supplier Intelligence — AutoFill Workbook (180 suppliers)
A2: Purpose | B2: Collect 180 verified manufacturers + exporters with emails, mapped to Zomorod categories, with evidence links and risk scoring.
A3: How it works | B3: Run the scraper in Codespaces to auto-fill 'Supplier_Intelligence'. Fix A: use multi-source crawling + Seed_URLs. Fix B: increase Max_Pages/Max_Items in Source_Config.
A4: Categories | B4: Wound Care; Syringes & Needles; IV Cannulas; IV Infusion Sets; Catheters; Gloves; PPE; Gauze & Bandages; Disinfectants; Lab Consumables
A6: Minimum acceptance rule | B6: Rows must have: Company + Email(s) + Country + Primary_Category + Evidence_URL.

Sheet Supplier_Intelligence
A1: Supplier_ID | B1: Company | C1: Country | D1: Supplier_Type | E1: Primary_Category | F1: Secondary_Categories | G1: Product_Focus (free text) | H1: Website | I1: Email(s) | J1: Phone/WhatsApp | K1: Export_Experience (explicit) | L1: Cert_ISO13485_Claim | M1: Cert_CE_Claim | N1: Cert_Other (FDA/UKCA/etc.) | O1: Evidence_URL (email or cert claim page) | P1: Expected_Price_Range_USD (sanity check) | Q1: Risk_Score (0=low,100=high) | R1: Risk_Level | S1: Status | T1: Last_Checked | U1: Notes
A2: 1 | B2: MAX Meditech Pvt. Ltd. - Leading Manufacturer of High-Quality Medical Devices for Mechanical Ventilation | D2: Manufacturer | E2: PPE | F2: Wound Care, Lab Consumables, Syringes & Needles, IV Infusion Sets, Gauze & Bandages, Disinfectants, IV Cannulas, Catheters | H2: https://www.medzell.net/main-categories-application/therapeutic-devices/ | I2: jithu.t@maxventilator.com | L2: Stated | N2: TUV | O2: https://www.medzell.net/company/a-b-industries/ | Q2: 10 | R2: =IF(Q2="","",IF(Q2>=60,"HIGH",IF(Q2>=30,"MEDIUM","LOW"))) | S2: New | T2: 2026-03-05 | U2: Seed=Medzell; Seed-file: output/medzell_company_urls.txt
A3: 2 | B3: Aadhar Medicare: Innovative Knee Supports, Body Belts, and Medical Devices | D3: Manufacturer | E3: PPE | F3: Wound Care, Gauze & Bandages, Lab Consumables, Syringes & Needles, IV Infusion Sets, Disinfectants, IV Cannulas, Catheters | H3: https://www.medzell.net/main-categories-application/therapeutic-devices/ | I3: sales@aadharmedicare.com | N3: TUV | O3: https://www.medzell.net/company/aadhar-medicare-private-limited/ | Q3: 25 | R3: =IF(Q3="","",IF(Q3>=60,"HIGH",IF(Q3>=30,"MEDIUM","LOW"))) | S3: New | T3: 2026-03-05 | U3: Seed=Medzell; Seed-file: output/medzell_company_urls.txt
A4: 3 | B4: aap Implantate AG | Leading Global Medical Technology for Trauma Care | D4: Manufacturer | E4: PPE | F4: Wound Care, Lab Consumables, Syringes & Needles, IV Infusion Sets, Gauze & Bandages, Disinfectants, IV Cannulas, Catheters | H4: https://www.medzell.net/main-categories-application/therapeutic-devices/ | I4: r.behrens@aap.de | N4: FDA, TUV | O4: https://www.medzell.net/company/aap-implantate-ag/ | Q4: 25 | R4: =IF(Q4="","",IF(Q4>=60,"HIGH",IF(Q4>=30,"MEDIUM","LOW"))) | S4: New | T4: 2026-03-05 | U4: Seed=Medzell; Seed-file: output/medzell_company_urls.txt
A5: 4 | B5: Revolutionary Post-Mastectomy Care Solutions | Aarna Biomedical Products Private Limited | D5: Manufacturer | E5: PPE | F5: Wound Care, Lab Consumables, Syringes & Needles, IV Infusion Sets, Gauze & Bandages, Disinfectants, IV Cannulas, Catheters | H5: https://www.medzell.net/main-categories-application/therapeutic-devices/ | I5: pawan.paterson@gmail.com | L5: Stated | N5: TUV | O5: https://www.medzell.net/company/aarna-biomedical-products-private-limited/ | Q5: 30 | R5: =IF(Q5="","",IF(Q5>=60,"HIGH",IF(Q5>=30,"MEDIUM","LOW"))) | S5: New | T5: 2026-03-05 | U5: Seed=Medzell; Seed-file: output/medzell_company_urls.txt
A6: 5 | B6: Accurex Biomedical Pvt. Ltd. - Leading Manufacturer of High-Quality Medical Diagnostic Solutions | D6: Manufacturer | E6: PPE | F6: Wound Care, Lab Consumables, Syringes & Needles, IV Infusion Sets, Gauze & Bandages, Disinfectants, IV Cannulas, Catheters | H6: https://www.medzell.net/main-categories-application/therapeutic-devices/ | I6: online1@accurex.net | N6: TUV | O6: https://www.medzell.net/company/accurex-biomedical-pvt-ltd/ | Q6: 25 | R6: =IF(Q6="","",IF(Q6>=60,"HIGH",IF(Q6>=30,"MEDIUM","LOW"))) | S6: New | T6: 2026-03-05 | U6: Seed=Medzell; Seed-file: output/medzell_company_urls.txt
A7: 6 | B7: Ace Cathtech – Indian Manufacturer of Catheterization, Nephrology & Critical Care Devices | D7: Manufacturer | E7: PPE | F7: Wound Care, Lab Consumables, Syringes & Needles, IV Infusion Sets, Gauze & Bandages, Disinfectants, IV Cannulas, Catheters | H7: https://www.medzell.net/main-categories-application/therapeutic-devices/ | I7: puneet.dohan1001@gmail.com | L7: Stated | N7: FDA, TUV | O7: https://www.medzell.net/company/ace-cathtech-pvt-ltd/ | Q7: 30 | R7: =IF(Q7="","",IF(Q7>=60,"HIGH",IF(Q7>=30,"MEDIUM","LOW"))) | S7: New | T7: 2026-03-05 | U7: Seed=Medzell; Seed-file: output/medzell_company_urls.txt
A8: 7 | B8: High-Quality Surgical Disposables, Hospital/Pharma Disposable Wear, and Cosmetic Products - Acuron Products | D8: Manufacturer | E8: PPE | F8: Wound Care, Lab Consumables, Syringes & Needles, IV Infusion Sets, Gauze & Bandages, Disinfectants, IV Cannulas, Catheters | H8: https://www.medzell.net/main-categories-application/therapeutic-devices/ | I8: acuronmarketing@gmail.com | N8: TUV | O8: https://www.medzell.net/company/acuron-products/ | Q8: 45 | R8: =IF(Q8="","",IF(Q8>=60,"HIGH",IF(Q8>=30,"MEDIUM","LOW"))) | S8: New | T8: 2026-03-05 | U8: Seed=Medzell; Seed-file: output/medzell_company_urls.txt
A9: 8 | B9: Adonis Medical Systems: Quality Imaging Solutions | D9: Manufacturer | E9: PPE | F9: Wound Care, Lab Consumables, Syringes & Needles, IV Infusion Sets, Gauze & Bandages, Disinfectants, IV Cannulas, Catheters | H9: https://www.medzell.net/main-categories-application/therapeutic-devices/ | I9: support@adonismedical.com | L9: Stated | N9: TUV | O9: https://www.medzell.net/company/adonis-medical-systems-private-limited/ | Q9: 10 | R9: =IF(Q9="","",IF(Q9>=60,"HIGH",IF(Q9>=30,"MEDIUM","LOW"))) | S9: New | T9: 2026-03-05 | U9: Seed=Medzell; Seed-file: output/medzell_company_urls.txt
A10: 9 | B10: Adva Medical: Innovative Surgical Products for Healthcare Professionals | D10: Manufacturer | E10: PPE | F10: Wound Care, Lab Consumables, Syringes & Needles, IV Infusion Sets, Gauze & Bandages, Disinfectants, IV Cannulas, Catheters | H10: https://www.medzell.net/main-categories-application/therapeutic-devices/ | I10: nazish.advamedical@gmail.com | L10: Stated | M10: Stated | N10: GMP, TUV | O10: https://www.medzell.net/company/adva-medical-india-pvt-ltd/ | Q10: 20 | R10: =IF(Q10="","",IF(Q10>=60,"HIGH",IF(Q10>=30,"MEDIUM","LOW"))) | S10: New | T10: 2026-03-05 | U10: Seed=Medzell; Seed-file: output/medzell_company_urls.txt
A11: 10 | B11: Premier Manufacturer and Global Supplier of NICU Equipment in India - Advance Mediplus Pvt. Ltd. | D11: Manufacturer | E11: PPE | F11: Wound Care, Lab Consumables, Syringes & Needles, IV Infusion Sets, Gauze & Bandages, Disinfectants, IV Cannulas, Catheters | H11: https://www.medzell.net/main-categories-application/therapeutic-devices/ | I11: contact@advancemedi.com | L11: Stated | N11: TUV | O11: https://www.medzell.net/company/advance-mediplus-pvt-ltd/ | Q11: 10 | R11: =IF(Q11="","",IF(Q11>=60,"HIGH",IF(Q11>=30,"MEDIUM","LOW"))) | S11: New | T11: 2026-03-05 | U11: Seed=Medzell; Seed-file: output/medzell_company_urls.txt
A12: 11 | B12: Discover Advanced LifeSciences Pvt. Ltd.: Pioneering B2B Manufacturer Bringing New Medical Technologies to the Indian Market | D12: Manufacturer | E12: PPE | F12: Wound Care, Lab Consumables, Syringes & Needles, IV Infusion Sets, Gauze & Bandages, Disinfectants, IV Cannulas, Catheters | H12: https://www.medzell.net/main-categories-application/therapeutic-devices/ | I12: sales@alspl.com | L12: Stated | M12: Stated | N12: TUV | O12: https://www.medzell.net/company/advanced-lifesciences-pvt-ltd/ | Q12: 0 | R12: =IF(Q12="","",IF(Q12>=60,"HIGH",IF(Q12>=30,"MEDIUM","LOW"))) | S12: New | T12: 2026-03-05 | U12: Seed=Medzell; Seed-file: output/medzell_company_urls.txt
A13: 12 | B13: Leading Global Manufacturer of Affordable and Accessible Medical Devices - Advanced MedTech Solutions Pvt. Ltd. | D13: Manufacturer | E13: PPE | F13: Wound Care, Lab Consumables, Syringes & Needles, IV Infusion Sets, Gauze & Bandages, Disinfectants, IV Cannulas, Catheters | H13: https://www.medzell.net/main-categories-application/therapeutic-devices/ | I13: shreenivass@amsltd.com | L13: Stated | N13: FDA, TUV | O13: https://www.medzell.net/company/advanced-medtech-solutions-pvt-ltd/ | Q13: 10 | R13: =IF(Q13="","",IF(Q13>=60,"HIGH",IF(Q13>=30,"MEDIUM","LOW"))) | S13: New | T13: 2026-03-05 | U13: Seed=Medzell; Seed-file: output/medzell_company_urls.txt
A14: 13 | B14: Advin Health Care – Global Manufacturer of Urology, Laparoscopy, Gynecology, Nephrology, Cardiology & Gastrology Devices | D14: Manufacturer | E14: PPE | F14: Wound Care, Lab Consumables, Syringes & Needles, IV Infusion Sets, Catheters, Gauze & Bandages, Disinfectants, IV Cannulas | H14: https://www.medzell.net/main-categories-application/therapeutic-devices/ | I14: advinhealthcare@gmail.com | L14: Stated | N14: TUV | O14: https://www.medzell.net/company/advin-health-care/ | Q14: 30 | R14: =IF(Q14="","",IF(Q14>=60,"HIGH",IF(Q14>=30,"MEDIUM","LOW"))) | S14: New | T14: 2026-03-05 | U14: Seed=Medzell; Seed-file: output/medzell_company_urls.txt
A15: 14 | B15: Aegis Lifesciences – Global Leader in Haemostatic & Surgical Medical Devices | D15: Manufacturer | E15: PPE | F15: Wound Care, Lab Consumables, Syringes & Needles, IV Infusion Sets, Gauze & Bandages, Disinfectants, IV Cannulas, Catheters | H15: https://www.medzell.net/main-categories-application/therapeutic-devices/ | I15: marketing.d@aegis-lifesciences.com | L15: Stated | M15: Stated | N15: FDA, GMP, TUV | O15: https://www.medzell.net/company/aegis-lifesciences-pvt-ltd/ | Q15: 0 | R15: =IF(Q15="","",IF(Q15>=60,"HIGH",IF(Q15>=30,"MEDIUM","LOW"))) | S15: New | T15: 2026-03-05 | U15: Seed=Medzell; Seed-file: output/medzell_company_urls.txt
A16: 15 | B16: Aether Biomedical | Advancing Bionic Prosthetics with Cutting-Edge Technology | D16: Manufacturer | E16: PPE | F16: Wound Care, Lab Consumables, Syringes & Needles, IV Infusion Sets, Gauze & Bandages, Disinfectants, IV Cannulas, Catheters | H16: https://www.medzell.net/main-categories-application/therapeutic-devices/ | I16: faith@aetherbiomedical.com | L16: Stated | N16: FDA, TUV | O16: https://www.medzell.net/company/aether-biomedical-sp-zo-o-prosthetics/ | Q16: 10 | R16: =IF(Q16="","",IF(Q16>=60,"HIGH",IF(Q16>=30,"MEDIUM","LOW"))) | S16: New | T16: 2026-03-05 | U16: Seed=Medzell; Seed-file: output/medzell_company_urls.txt
A17: 16 | B17: Affigenix Biosolutions Pvt. Ltd.: Tailored Biosolutions for Life Science and Diagnostics Sectors in India | D17: Manufacturer | E17: PPE | F17: Wound Care, Lab Consumables, Syringes & Needles, IV Infusion Sets, Gauze & Bandages, Disinfectants, IV Cannulas, Catheters | H17: https://www.medzell.net/main-categories-application/therapeutic-devices/ | I17: sales@affigenix.com | L17: Stated | N17: TUV | O17: https://www.medzell.net/company/affigenix-biosolutions-private-limited/ | Q17: 10 | R17: =IF(Q17="","",IF(Q17>=60,"HIGH",IF(Q17>=30,"MEDIUM","LOW"))) | S17: New | T17: 2026-03-05 | U17: Seed=Medzell; Seed-file: output/medzell_company_urls.txt
A18: 17 | B18: Agappe Diagnostics: Global Leader in In-Vitro Diagnostics | ISO Certified Manufacturer | D18: Manufacturer | E18: PPE | F18: Wound Care, Lab Consumables, Syringes & Needles, IV Infusion Sets, Gauze & Bandages, Disinfectants, IV Cannulas, Catheters | H18: https://www.medzell.net/main-categories-application/therapeutic-devices/ | I18: sreevisakh.kl@agappe.in | L18: Stated | N18: FDA, GMP, TUV | O18: https://www.medzell.net/company/agappe-diagnostics-limited/ | Q18: 10 | R18: =IF(Q18="","",IF(Q18>=60,"HIGH",IF(Q18>=30,"MEDIUM","LOW"))) | S18: New | T18: 2026-03-05 | U18: Seed=Medzell; Seed-file: output/medzell_company_urls.txt
A19: 18 | B19: AGD Biomedicals Pvt Ltd: Leading Manufacturer of Laboratory and IVD Equipment | D19: Manufacturer | E19: PPE | F19: Wound Care, Lab Consumables, Syringes & Needles, IV Infusion Sets, Gauze & Bandages, Disinfectants, IV Cannulas, Catheters | H19: https://www.medzell.net/main-categories-application/therapeutic-devices/ | I19: prabhat.sk77@gmail.com | L19: Stated | N19: TUV | O19: https://www.medzell.net/company/agd-biomedicals-pvt-ltd/ | Q19: 30 | R19: =IF(Q19="","",IF(Q19>=60,"HIGH",IF(Q19>=30,"MEDIUM","LOW"))) | S19: New | T19: 2026-03-05 | U19: Seed=Medzell; Seed-file: output/medzell_company_urls.txt
A20: 19 | B20: AI-OPTIC | Innovating Vision Screening with AI-Powered Technology | D20: Manufacturer | E20: PPE | F20: Wound Care, Lab Consumables, Syringes & Needles, IV Infusion Sets, Gauze & Bandages, Disinfectants, IV Cannulas, Catheters | H20: https://www.medzell.net/main-categories-application/therapeutic-devices/ | I20: helen@ai-optic.com | L20: Stated | N20: FDA, TUV | O20: https://www.medzell.net/company/ai-optic/ | Q20: 10 | R20: =IF(Q20="","",IF(Q20>=60,"HIGH",IF(Q20>=30,"MEDIUM","LOW"))) | S20: New | T20: 2026-03-05 | U20: Seed=Medzell; Seed-file: output/medzell_company_urls.txt
A21: 20 | B21: Aidlab - Empowering Remote Health, Fitness, and Science with Advanced Wearables | D21: Manufacturer | E21: PPE | F21: Wound Care, Lab Consumables, Syringes & Needles, IV Infusion Sets, Gauze & Bandages, Disinfectants, IV Cannulas, Catheters | H21: https://www.medzell.net/main-categories-application/therapeutic-devices/ | I21: jdomaszewicz@aidlab.com | L21: Stated | N21: TUV | O21: https://www.medzell.net/company/aidlab-inc/ | Q21: 10 | R21: =IF(Q21="","",IF(Q21>=60,"HIGH",IF(Q21>=30,"MEDIUM","LOW"))) | S21: New | T21: 2026-03-05 | U21: Seed=Medzell; Seed-file: output/medzell_company_urls.txt
A22: 21 | B22: Airgases Projects – Trusted Partner in Medical & Industrial Gas Solutions | D22: Manufacturer | E22: PPE | F22: Wound Care, Lab Consumables, Syringes & Needles, IV Infusion Sets, Gauze & Bandages, Disinfectants, IV Cannulas, Catheters | H22: https://www.medzell.net/main-categories-application/therapeutic-devices/ | I22: benganinamrata@gmail.com | L22: Stated | N22: TUV | O22: https://www.medzell.net/company/airgases-projects-pvt-ltd/ | Q22: 30 | R22: =IF(Q22="","",IF(Q22>=60,"HIGH",IF(Q22>=30,"MEDIUM","LOW"))) | S22: New | T22: 2026-03-05 | U22: Seed=Medzell; Seed-file: output/medzell_company_urls.txt
A23: 22 | B23: Airox Technologies: Pioneers and Leaders in PSA Oxygen Generation | D23: Manufacturer | E23: PPE | F23: Wound Care, Lab Consumables, Syringes & Needles, IV Infusion Sets, Gauze & Bandages, Disinfectants, IV Cannulas, Catheters | H23: https://www.medzell.net/main-categories-application/therapeutic-devices/ | I23: sales@airoxtechnologies.com | N23: TUV | O23: https://www.medzell.net/company/airox-technologies-limited/ | Q23: 25 | R23: =IF(Q23="","",IF(Q23>=60,"HIGH",IF(Q23>=30,"MEDIUM","LOW"))) | S23: New | T23: 2026-03-05 | U23: Seed=Medzell; Seed-file: output/medzell_company_urls.txt
A24: 23 | B24: Leading Manufacturer & Exporter of Hospital Consumables - Airways Surgical Pvt. Ltd. | D24: Manufacturer | E24: PPE | F24: Wound Care, Lab Consumables, Syringes & Needles, IV Infusion Sets, Gauze & Bandages, Disinfectants, IV Cannulas, Catheters | H24: https://www.medzell.net/main-categories-application/therapeutic-devices/ | I24: info@airwayssurgical.com | L24: Stated | N24: TUV | O24: https://www.medzell.net/company/airways-surgical-pvt-ltd/ | Q24: 10 | R24: =IF(Q24="","",IF(Q24>=60,"HIGH",IF(Q24>=30,"MEDIUM","LOW"))) | S24: New | T24: 2026-03-05 | U24: Seed=Medzell; Seed-file: output/medzell_company_urls.txt
A25: 24 | B25: AKAS Infusions: Trusted Manufacturer of High-Quality Drug Delivery Systems | D25: Manufacturer | E25: PPE | F25: Wound Care, Lab Consumables, Syringes & Needles, IV Infusion Sets, Gauze & Bandages, Disinfectants, IV Cannulas, Catheters | H25: https://www.medzell.net/main-categories-application/therapeutic-devices/ | I25: girish@akasinfusions.com | L25: Stated | M25: Stated | N25: TUV | O25: https://www.medzell.net/company/akas-infusions/ | Q25: 0 | R25: =IF(Q25="","",IF(Q25>=60,"HIGH",IF(Q25>=30,"MEDIUM","LOW"))) | S25: New | T25: 2026-03-05 | U25: Seed=Medzell; Seed-file: output/medzell_company_urls.txt
A26: 25 | B26: AKAS Technologies: Leading Manufacturer of Cutting-Edge Ophthalmology Products and Solutions | D26: Manufacturer | E26: PPE | F26: Wound Care, Lab Consumables, Syringes & Needles, IV Infusion Sets, Gauze & Bandages, Disinfectants, IV Cannulas, Catheters | H26: https://www.medzell.net/main-categories-application/therapeutic-devices/ | I26: exportakastech@gmail.com | L26: Stated | N26: TUV | O26: https://www.medzell.net/company/akas-technologies/ | Q26: 30 | R26: =IF(Q26="","",IF(Q26>=60,"HIGH",IF(Q26>=30,"MEDIUM","LOW"))) | S26: New | T26: 2026-03-05 | U26: Seed=Medzell; Seed-file: output/medzell_company_urls.txt
A27: 26 | B27: Akriti – Innovating Affordable Eye Care Solutions & Ophthalmic Implants | D27: Manufacturer | E27: PPE | F27: Wound Care, Lab Consumables, Syringes & Needles, IV Infusion Sets, Gauze & Bandages, Disinfectants, IV Cannulas, Catheters | H27: https://www.medzell.net/main-categories-application/therapeutic-devices/ | I27: sales.akriti@gmail.com | N27: TUV | O27: https://www.medzell.net/company/akriti-ophthalmic-pvt-ltd/ | Q27: 45 | R27: =IF(Q27="","",IF(Q27>=60,"HIGH",IF(Q27>=30,"MEDIUM","LOW"))) | S27: New | T27: 2026-03-05 | U27: Seed=Medzell; Seed-file: output/medzell_company_urls.txt
A28: 27 | B28: Quality, Reliability, and Innovation: A Deep Dive into Alan Electronic Systems Pvt. Ltd., Featuring CO2 Insufflators and ESUs. | D28: Manufacturer | E28: PPE | F28: Wound Care, Lab Consumables, Syringes & Needles, IV Infusion Sets, Gauze & Bandages, Disinfectants, IV Cannulas, Catheters | H28: https://www.medzell.net/main-categories-application/therapeutic-devices/ | I28: export@alanindia.net | L28: Stated | N28: TUV | O28: https://www.medzell.net/company/alan-electronics-systems-pvt-ltd/ | Q28: 10 | R28: =IF(Q28="","",IF(Q28>=60,"HIGH",IF(Q28>=30,"MEDIUM","LOW"))) | S28: New | T28: 2026-03-05 | U28: Seed=Medzell; Seed-file: output/medzell_company_urls.txt
A29: 28 | B29: Top-Quality Medical Imaging Solutions by Allans Medical Systems Pvt. Ltd. | D29: Manufacturer | E29: PPE | F29: Wound Care, Lab Consumables, Syringes & Needles, IV Infusion Sets, Gauze & Bandages, Disinfectants, IV Cannulas, Catheters | H29: https://www.medzell.net/main-categories-application/therapeutic-devices/ | I29: allansmedisys@gmail.com | N29: TUV | O29: https://www.medzell.net/company/allans-medical-systems-pvt-ltd/ | Q29: 45 | R29: =IF(Q29="","",IF(Q29>=60,"HIGH",IF(Q29>=30,"MEDIUM","LOW"))) | S29: New | T29: 2026-03-05 | U29: Seed=Medzell; Seed-file: output/medzell_company_urls.txt
A30: 29 | B30: Allengers Medical Systems Ltd. | India’s Premier Diagnostic Equipment Manufacturer | D30: Manufacturer | E30: PPE | F30: Wound Care, Lab Consumables, Syringes & Needles, IV Infusion Sets, Catheters, Gauze & Bandages, Disinfectants, IV Cannulas | H30: https://www.medzell.net/main-categories-application/therapeutic-devices/ | I30: online.marketing@allengers.net | L30: Stated | N30: FDA, TUV | O30: https://www.medzell.net/company/allengers-medical-systems-ltd/ | Q30: 10 | R30: =IF(Q30="","",IF(Q30>=60,"HIGH",IF(Q30>=30,"MEDIUM","LOW"))) | S30: New | T30: 2026-03-05 | U30: Seed=Medzell; Seed-file: output/medzell_company_urls.txt
A31: 30 | B31: Alliance Elemech – Trusted Manufacturer of Medical & Industrial Sterilization Equipment | D31: Manufacturer | E31: PPE | F31: Wound Care, Lab Consumables, Syringes & Needles, IV Infusion Sets, Gauze & Bandages, Disinfectants, IV Cannulas, Catheters | H31: https://www.medzell.net/main-categories-application/therapeutic-devices/ | I31: alliance.elemech@gmail.com | N31: TUV | O31: https://www.medzell.net/company/alliance-elemech/ | Q31: 45 | R31: =IF(Q31="","",IF(Q31>=60,"HIGH",IF(Q31>=30,"MEDIUM","LOW"))) | S31: New | T31: 2026-03-05 | U31: Seed=Medzell; Seed-file: output/medzell_company_urls.txt
A32: 31 | B32: Leading Manufacturer and Exporter of Hospital Equipment - Allied Medical Limited (AML) | D32: Manufacturer | E32: PPE | F32: Wound Care, Lab Consumables, Syringes & Needles, IV Infusion Sets, Gauze & Bandages, Disinfectants, IV Cannulas, Catheters | H32: https://www.medzell.net/main-categories-application/therapeutic-devices/ | I32: godwin@alliedmed.co.in | L32: Stated | M32: Stated | N32: FDA, TUV | O32: https://www.medzell.net/company/allied-medical-ltd/ | Q32: 0 | R32: =IF(Q32="","",IF(Q32>=60,"HIGH",IF(Q32>=30,"MEDIUM","LOW"))) | S32: New | T32: 2026-03-05 | U32: Seed=Medzell; Seed-file: output/medzell_company_urls.txt
A33: 32 | B33: Alpine Biomedicals – Advancing Rapid Diagnostics for Accurate & Cost-Effective Healthcare Solutions | D33: Manufacturer | E33: PPE | F33: Wound Care, Lab Consumables, Syringes & Needles, IV Infusion Sets, Gauze & Bandages, Disinfectants, IV Cannulas, Catheters | H33: https://www.medzell.net/main-categories-application/therapeutic-devices/ | I33: sales@alpinebiomedicals.com | L33: Stated | N33: TUV | O33: https://www.medzell.net/company/alpine-biomedicals-pvt-ltd/ | Q33: 10 | R33: =IF(Q33="","",IF(Q33>=60,"HIGH",IF(Q33>=30,"MEDIUM","LOW"))) | S33: New | T33: 2026-03-05 | U33: Seed=Medzell; Seed-file: output/medzell_company_urls.txt
A34: 33 | B34: Altis Instruments - Trusted Lab Furnaces, Ovens & Sterilizer Solutions | D34: Manufacturer | E34: PPE | F34: Wound Care, Lab Consumables, Syringes & Needles, IV Infusion Sets, Gauze & Bandages, Disinfectants, IV Cannulas, Catheters | H34: https://www.medzell.net/main-categories-application/therapeutic-devices/ | I34: altisinstrumentsindia@gmail.com | L34: Stated | N34: FDA, GMP, TUV | O34: https://www.medzell.net/company/altis-instruments/ | Q34: 30 | R34: =IF(Q34="","",IF(Q34>=60,"HIGH",IF(Q34>=30,"MEDIUM","LOW"))) | S34: New | T34: 2026-03-05 | U34: Seed=Medzell; Seed-file: output/medzell_company_urls.txt
A35: 34 | B35: Amazing Rubber Products – Premium Medical Gloves for Global Healthcare | D35: Manufacturer | E35: PPE | F35: Wound Care, Lab Consumables, Syringes & Needles, IV Infusion Sets, Gloves, Gauze & Bandages, Disinfectants, IV Cannulas, Catheters | H35: https://www.medzell.net/main-categories-application/therapeutic-devices/ | I35: inquiries@amazingglove.com | L35: Stated | N35: FDA, GMP, TUV | O35: https://www.medzell.net/company/amazing-rubber-products-pvt-ltd/ | Q35: 10 | R35: =IF(Q35="","",IF(Q35>=60,"HIGH",IF(Q35>=30,"MEDIUM","LOW"))) | S35: New | T35: 2026-03-05 | U35: Seed=Medzell; Seed-file: output/medzell_company_urls.txt
A36: 35 | B36: AMBELIO - Innovative Medical Devices for Pain Management | D36: Manufacturer | E36: PPE | F36: Wound Care, Lab Consumables, Syringes & Needles, IV Infusion Sets, Gauze & Bandages, Disinfectants, IV Cannulas, Catheters | H36: https://www.medzell.net/main-categories-application/therapeutic-devices/ | I36: achats@ambelio.com | N36: TUV | O36: https://www.medzell.net/company/ambelio/ | Q36: 25 | R36: =IF(Q36="","",IF(Q36>=60,"HIGH",IF(Q36>=30,"MEDIUM","LOW"))) | S36: New | T36: 2026-03-05 | U36: Seed=Medzell; Seed-file: output/medzell_company_urls.txt
A37: 36 | B37: Eqwell – Your Reliable Partner for Surgical Dressings & Medical Supplies | D37: Manufacturer | E37: PPE | F37: Wound Care, Gauze & Bandages, Lab Consumables, Syringes & Needles, IV Infusion Sets, Disinfectants, IV Cannulas, Catheters | H37: https://www.medzell.net/main-categories-application/therapeutic-devices/ | I37: ambikatraders555@gmail.com | N37: TUV | O37: https://www.medzell.net/company/ambika-traders-eqwell/ | Q37: 45 | R37: =IF(Q37="","",IF(Q37>=60,"HIGH",IF(Q37>=30,"MEDIUM","LOW"))) | S37: New | T37: 2026-03-05 | U37: Seed=Medzell; Seed-file: output/medzell_company_urls.txt
A38: 37 | B38: Ambinova Technologies: Precision-Engineered Laboratory Solutions | D38: Manufacturer | E38: PPE | F38: Wound Care, Lab Consumables, Syringes & Needles, IV Infusion Sets, Gauze & Bandages, Disinfectants, IV Cannulas, Catheters | H38: https://www.medzell.net/main-categories-application/therapeutic-devices/ | I38: paul@ambinova.in | N38: TUV | O38: https://www.medzell.net/company/ambinova-technologies-pvt-ltd/ | Q38: 25 | R38: =IF(Q38="","",IF(Q38>=60,"HIGH",IF(Q38>=30,"MEDIUM","LOW"))) | S38: New | T38: 2026-03-05 | U38: Seed=Medzell; Seed-file: output/medzell_company_urls.txt
A39: 38 | B39: Leading Manufacturer of Medical Tubing and Consumables - Ami Polymer Pvt. Ltd. | D39: Manufacturer | E39: PPE | F39: Wound Care, Lab Consumables, Syringes & Needles, IV Cannulas, IV Infusion Sets, Gauze & Bandages, Disinfectants, Catheters | H39: https://www.medzell.net/main-categories-application/therapeutic-devices/ | I39: anuj.s@amipolymer.com | L39: Stated | N39: FDA, TUV | O39: https://www.medzell.net/company/ami-polymer-pvt-ltd/ | Q39: 10 | R39: =IF(Q39="","",IF(Q39>=60,"HIGH",IF(Q39>=30,"MEDIUM","LOW"))) | S39: New | T39: 2026-03-05 | U39: Seed=Medzell; Seed-file: output/medzell_company_urls.txt
A40: 39 | B40: AMX Medical Systems: Top Manufacturer & Supplier of Advanced X-Ray Machines | D40: Manufacturer | E40: PPE | F40: Wound Care, Lab Consumables, Syringes & Needles, IV Infusion Sets, Gauze & Bandages, Disinfectants, IV Cannulas, Catheters | H40: https://www.medzell.net/main-categories-application/therapeutic-devices/ | I40: amxmedicalsystems@gmail.com | L40: Stated | N40: TUV | O40: https://www.medzell.net/company/amx-medical-systems/ | Q40: 30 | R40: =IF(Q40="","",IF(Q40>=60,"HIGH",IF(Q40>=30,"MEDIUM","LOW"))) | S40: New | T40: 2026-03-05 | U40: Seed=Medzell; Seed-file: output/medzell_company_urls.txt
...

Sheet Seed_URLs
A1: Seed URLs (Fix A) — paste directory/company pages here (500+). Scraper will extract emails + map categories and fill Supplier_Intelligence up to 180.
A2: Source_Name | B2: Country | C2: URL | D2: Category_Hint | E2: Notes | F2: Use (TRUE/FALSE)
A3: Medzell | C3: https://www.medzell.net/sitemap.xml | E3: seed sitemap | F3: TRUE
A4: Turkey_TurkishHealthcare | B4: Turkey | C4: https://turkishhealthcare.org/companies | E4: directory start | F4: TRUE
A5: Malaysia_MMDA | B5: Malaysia | C5: https://mmda.org.my/mmda-members-list/ | E5: directory start | F5: TRUE
A6: China_CAMDI | B6: China | C6: https://en.camdi.cn/member/index | E6: directory start | F6: TRUE
A7: France_SNITEM | B7: France | C7: https://www.snitem.fr/adherer/entreprises-adherentes/ | E7: directory start | F7: TRUE
A8: Italy_ConfindustriaDM | B8: Italy | C8: https://www.confindustriadm.it/le-aziende/ | E8: directory start | F8: TRUE
A9: Spain_FENIN | B9: Spain | C9: https://fenin.es/socios/ | E9: directory start | F9: TRUE
A10: UK_ABHI | B10: United Kingdom | C10: https://www.abhi.org.uk/membership/member-search/ | E10: directory start | F10: TRUE
A11: Germany_SPECTARIS | B11: Germany | C11: https://www.spectaris.de/verband/mitglieder | E11: directory start | F11: TRUE
A12: Egypt_CCI | B12: Egypt | C12: https://cci-egypt.org/membership/members-profiles/all-cci-members | E12: directory start | F12: TRUE

Sheet Source_Config
A1: Source_Name | B1: Base_URL | C1: Strategy | D1: Max_Items | E1: Max_Pages | F1: Delay_Seconds | G1: Notes
A2: Medzell | B2: https://www.medzell.net/ | C2: sitemap_company_pages | D2: 3000 | E2: 0 | F2: 0.5 | G2: Malaysia glove manufacturers; high yield
A3: Turkey_TurkishHealthcare | B3: https://turkishhealthcare.org/companies | C3: directory | D3: 3000 | E3: 200 | F3: 0.8 | G3: Turkey manufacturers/exporters; moderate yield
A4: Malaysia_MMDA | B4: https://mmda.org.my/mmda-members-list/ | C4: directory | D4: 3000 | E4: 0 | F4: 0.8 | G4: Add Medzell company URLs into Seed_URLs
A5: China_CAMDI | B5: https://en.camdi.cn/member/index | C5: directory_paginated | D5: 3000 | E5: 50 | F5: 1 | G5: Paste exhibitor profile URLs into Seed_URLs
A6: France_SNITEM | B6: https://www.snitem.fr/adherer/entreprises-adherentes/ | C6: directory | D6: 3000 | E6: 0 | F6: 1 | G6: Paste exhibitor profile URLs into Seed_URLs
A7: Italy_ConfindustriaDM | B7: https://www.confindustriadm.it/le-aziende/ | C7: directory | D7: 3000 | E7: 0 | F7: 1
A8: Spain_FENIN | B8: https://fenin.es/socios/ | C8: directory | D8: 3000 | E8: 80 | F8: 1
A9: UK_ABHI | B9: https://www.abhi.org.uk/membership/member-search/ | C9: directory | D9: 3000 | E9: 80 | F9: 1
A10: Germany_SPECTARIS | B10: https://www.spectaris.de/verband/mitglieder | C10: directory | D10: 3000 | E10: 0 | F10: 1
A11: Egypt_CCI | B11: https://cci-egypt.org/membership/members-profiles/all-cci-members | C11: directory_paginated | D11: 3000 | E11: 100 | F11: 1.2

Sheet Category_Keywords
A1: Category | B1: Keywords (comma-separated) | C1: Notes
A2: Wound Care | B2: dressing, bandage, foam dressing, hydrocolloid, silicone dressing, wound, plaster
A3: Syringes & Needles | B3: syringe, needle, hypodermic, luer lock, luer slip, insulin syringe, scalp vein
A4: IV Cannulas | B4: iv cannula, cannula, venflon, iv catheter
A5: IV Infusion Sets | B5: infusion set, iv set, drip set, transfusion set, burette
A6: Catheters | B6: foley, catheter, suction catheter, nelaton, urinary catheter, urology
A7: Gloves | B7: nitrile glove, latex glove, vinyl glove, examination glove, surgical glove
A8: PPE | B8: mask, respirator, gown, coverall, face shield, cap, shoe cover
A9: Gauze & Bandages | B9: gauze, gauze roll, gauze swab, bandage roll, crepe bandage, cotton
A10: Disinfectants | B10: alcohol swab, disinfectant, sanitizer, antiseptic, povidone, chlorhexidine
A11: Lab Consumables | B11: vacutainer, tube, pipette, specimen, lancet, sample cup, centrifuge tube

Sheet Benchmarks
A1: Category | B1: Benchmark Source | C1: How to use | D1: Link/Reference
A2: All categories | B2: UNICEF Supply Catalogue | C2: Sanity-check quote ranges; not landed cost | D2: https://supply.unicef.org/all-materials/medical-renewable.html?cat=2871&p=2&product_attributes=10
A3: Gloves (example) | B3: UNICEF product page | C3: Sanity-check specs & pricing display | D3: https://supply.unicef.org/s0330126.html

Sheet Risk_Model
A1: Factor | B1: Rule | C1: Points Added | D1: Rationale
A2: Email quality | B2: Free email domain (gmail/yahoo) OR no company-domain email | C2: 20 | D2: Higher fraud/low-traceability risk
A3: ISO 13485 | B3: Not explicitly stated (or no evidence link) | C3: 15 | D3: Strong quality signal for medical devices
A4: CE | B4: Not explicitly stated (or no evidence link) | C4: 10 | D4: Useful conformity signal (where applicable)
A5: Evidence URL | B5: Missing evidence link for email/cert claims | C5: 15 | D5: Cannot verify quickly
A6: Export experience | B6: No explicit export markets/clients stated | C6: 10 | D6: Unknown export handling maturity
A7: Supplier type | B7: Exporter without manufacturer disclosure | C7: 10 | D7: Need factory validation

Sheet Run_Log
A1: Run_Timestamp | B1: Rows_Filled | C1: Sources_Used | D1: Notes
A2: 2026-03-04T20:40:09.227035Z | D2: Workbook generated. Run scraper in Codespaces to populate Supplier_Intelligence.
A3: 2026-03-05T00:21:02.419940+00:00 | B3: 0 | C3: MULTI|Malaysia|append | D3: Visited 1 seeds; wrote 0 NEW suppliers. limit=300 delay=0.8s
A4: 2026-03-05T00:21:06.145195+00:00 | B4: 0 | C4: MULTI|Turkey|append | D4: Visited 1 seeds; wrote 0 NEW suppliers. limit=300 delay=0.8s
A5: 2026-03-05T00:21:10.167447+00:00 | B5: 0 | C5: MULTI|China|append | D5: Visited 1 seeds; wrote 0 NEW suppliers. limit=300 delay=0.8s
A6: 2026-03-05T00:43:16.908770+00:00 | B6: 441 | C6: Medzell|ALL|append | D6: Visited 629 seeds; wrote 441 NEW suppliers. limit=600 delay=0.5s

Sheet Outreach_Batch
A1: Outreach Batch Builder (filters + export-ready list)
J2: Categories | K2: Countries | L2: RiskLevels
A3: Primary Category | D3: Filtered suppliers (Excel 365 dynamic formula). If your Excel doesn't support this, use the Python exporter script. | J3: Wound Care | K3: Malaysia | L3: LOW
A4: Country | D4: Company | E4: Email(s) | F4: Country | G4: Risk_Level | H4: Evidence_URL | J4: Syringes & Needles | K4: Turkey | L4: MED
A5: Max Risk Level | B5: MED | J5: IV Cannulas | K5: China | L5: HIGH
A6: Batch Size | B6: 100 | D6: =LET(cat,$B$3,cty,$B$4,maxRisk,$B$5,batchSize,$B$6,batchNum,$B$7,tbl,Supplier_Intelligence!$A$2:$U$3001,companies,INDEX(tbl,,2),emails,INDEX(tbl,,9),country,INDEX(tbl,,3),risk,INDEX(tbl,,18),evidence,INDEX(tbl,,15),isRisk,IF(maxRisk="LOW",risk="LOW",IF(maxRisk="MED",(risk="LOW")+(risk="MED"),1)),isCat,IF(cat="",1,INDEX(tbl,,5)=cat),isCty,IF(cty="",1,country=cty),mask,(companies<>"")*isRisk*isCat*isCty*(emails<>""),filtered,FILTER(HSTACK(companies,emails,country,risk,evidence),mask,""),start,(batchNum-1)*batchSize+1,TAKE(DROP(filtered,start-1),batchSize)) | J6: IV Infusion Sets | K6: India
A7: Batch # (1,2,3...) | B7: 1 | J7: Catheters | K7: Egypt
D8: =D6 | J8: Gloves | K8: Jordan
J9: PPE | K9: United Arab Emirates
J10: Gauze & Bandages | K10: Saudi Arabia
J11: Disinfectants | K11: Qatar
J12: Lab Consumables | K12: Kuwait
K13: Oman
K14: Bahrain
K15: Lebanon
K16: Iraq
K17: Yemen
K18: Palestine
K19: Germany
K20: France
K21: Italy
K22: Spain
K23: United Kingdom
K24: Syria

Sheet View_Malaysia
A1: View: Malaysia (filter by category + risk)
J2: Categories | K2: RiskLevels
A3: Category (optional) | D3: Filtered suppliers | J3: Wound Care | K3: LOW
A4: Max Risk (LOW/MED/HIGH) | B4: MED | D4: Supplier_ID | E4: Company | F4: Country | G4: Supplier_Type | H4: Primary_Category | I4: Secondary_Categories | J4: Syringes & Needles | K4: MED | L4: Risk_Level | M4: Evidence_URL
D5: =LET(cty,"Malaysia",cat,$B$3,maxRisk,$B$4,tbl,Supplier_Intelligence!$A$2:$U$3001,sid,INDEX(tbl,,1),co,INDEX(tbl,,2),country,INDEX(tbl,,3),stype,INDEX(tbl,,4),pcat,INDEX(tbl,,5),scat,INDEX(tbl,,6),web,INDEX(tbl,,8),em,INDEX(tbl,,9),risk,INDEX(tbl,,18),ev,INDEX(tbl,,15),isCty,country=cty,isCat,IF(cat="",1,pcat=cat),isRisk,IF(maxRisk="LOW",risk="LOW",IF(maxRisk="MED",(risk="LOW")+(risk="MED"),1)),mask,(co<>"")*(em<>"")*isCty*isCat*isRisk,FILTER(HSTACK(sid,co,country,stype,pcat,scat,web,em,risk,ev),mask,"")) | J5: IV Cannulas | K5: HIGH
J6: IV Infusion Sets
J7: Catheters
J8: Gloves
J9: PPE
J10: Gauze & Bandages
J11: Disinfectants
J12: Lab Consumables

Sheet View_Turkey
A1: View: Turkey (filter by category + risk)
J2: Categories | K2: RiskLevels
A3: Category (optional) | D3: Filtered suppliers | J3: Wound Care | K3: LOW
A4: Max Risk (LOW/MED/HIGH) | B4: MED | D4: Supplier_ID | E4: Company | F4: Country | G4: Supplier_Type | H4: Primary_Category | I4: Secondary_Categories | J4: Syringes & Needles | K4: MED | L4: Risk_Level | M4: Evidence_URL
D5: =LET(cty,"Turkey",cat,$B$3,maxRisk,$B$4,tbl,Supplier_Intelligence!$A$2:$U$3001,sid,INDEX(tbl,,1),co,INDEX(tbl,,2),country,INDEX(tbl,,3),stype,INDEX(tbl,,4),pcat,INDEX(tbl,,5),scat,INDEX(tbl,,6),web,INDEX(tbl,,8),em,INDEX(tbl,,9),risk,INDEX(tbl,,18),ev,INDEX(tbl,,15),isCty,country=cty,isCat,IF(cat="",1,pcat=cat),isRisk,IF(maxRisk="LOW",risk="LOW",IF(maxRisk="MED",(risk="LOW")+(risk="MED"),1)),mask,(co<>"")*(em<>"")*isCty*isCat*isRisk,FILTER(HSTACK(sid,co,country,stype,pcat,scat,web,em,risk,ev),mask,"")) | J5: IV Cannulas | K5: HIGH
J6: IV Infusion Sets
J7: Catheters
J8: Gloves
J9: PPE
J10: Gauze & Bandages
J11: Disinfectants
J12: Lab Consumables

Sheet View_China
A1: View: China (filter by category + risk)
J2: Categories | K2: RiskLevels
A3: Category (optional) | D3: Filtered suppliers | J3: Wound Care | K3: LOW
A4: Max Risk (LOW/MED/HIGH) | B4: MED | D4: Supplier_ID | E4: Company | F4: Country | G4: Supplier_Type | H4: Primary_Category | I4: Secondary_Categories | J4: Syringes & Needles | K4: MED | L4: Risk_Level | M4: Evidence_URL
D5: =LET(cty,"China",cat,$B$3,maxRisk,$B$4,tbl,Supplier_Intelligence!$A$2:$U$3001,sid,INDEX(tbl,,1),co,INDEX(tbl,,2),country,INDEX(tbl,,3),stype,INDEX(tbl,,4),pcat,INDEX(tbl,,5),scat,INDEX(tbl,,6),web,INDEX(tbl,,8),em,INDEX(tbl,,9),risk,INDEX(tbl,,18),ev,INDEX(tbl,,15),isCty,country=cty,isCat,IF(cat="",1,pcat=cat),isRisk,IF(maxRisk="LOW",risk="LOW",IF(maxRisk="MED",(risk="LOW")+(risk="MED"),1)),mask,(co<>"")*(em<>"")*isCty*isCat*isRisk,FILTER(HSTACK(sid,co,country,stype,pcat,scat,web,em,risk,ev),mask,"")) | J5: IV Cannulas | K5: HIGH
J6: IV Infusion Sets
J7: Catheters
J8: Gloves
J9: PPE
J10: Gauze & Bandages
J11: Disinfectants
J12: Lab Consumables

Sheet View_Egypt
A1: View: Egypt (filter by category + risk)
J2: Categories | K2: RiskLevels
A3: Category (optional) | D3: Filtered suppliers | J3: Wound Care | K3: LOW
A4: Max Risk (LOW/MED/HIGH) | B4: MED | D4: Supplier_ID | E4: Company | F4: Country | G4: Supplier_Type | H4: Primary_Category | I4: Secondary_Categories | J4: Syringes & Needles | K4: MED | L4: Risk_Level | M4: Evidence_URL
D5: =LET(cty,"Egypt",cat,$B$3,maxRisk,$B$4,tbl,Supplier_Intelligence!$A$2:$U$3001,sid,INDEX(tbl,,1),co,INDEX(tbl,,2),country,INDEX(tbl,,3),stype,INDEX(tbl,,4),pcat,INDEX(tbl,,5),scat,INDEX(tbl,,6),web,INDEX(tbl,,8),em,INDEX(tbl,,9),risk,INDEX(tbl,,18),ev,INDEX(tbl,,15),isCty,country=cty,isCat,IF(cat="",1,pcat=cat),isRisk,IF(maxRisk="LOW",risk="LOW",IF(maxRisk="MED",(risk="LOW")+(risk="MED"),1)),mask,(co<>"")*(em<>"")*isCty*isCat*isRisk,FILTER(HSTACK(sid,co,country,stype,pcat,scat,web,em,risk,ev),mask,"")) | J5: IV Cannulas | K5: HIGH
J6: IV Infusion Sets
J7: Catheters
J8: Gloves
J9: PPE
J10: Gauze & Bandages
J11: Disinfectants
J12: Lab Consumables

Sheet View_Germany
A1: View: Germany (filter by category + risk)
J2: Categories | K2: RiskLevels
A3: Category (optional) | D3: Filtered suppliers | J3: Wound Care | K3: LOW
A4: Max Risk (LOW/MED/HIGH) | B4: MED | D4: Supplier_ID | E4: Company | F4: Country | G4: Supplier_Type | H4: Primary_Category | I4: Secondary_Categories | J4: Syringes & Needles | K4: MED | L4: Risk_Level | M4: Evidence_URL
D5: =LET(cty,"Germany",cat,$B$3,maxRisk,$B$4,tbl,Supplier_Intelligence!$A$2:$U$3001,sid,INDEX(tbl,,1),co,INDEX(tbl,,2),country,INDEX(tbl,,3),stype,INDEX(tbl,,4),pcat,INDEX(tbl,,5),scat,INDEX(tbl,,6),web,INDEX(tbl,,8),em,INDEX(tbl,,9),risk,INDEX(tbl,,18),ev,INDEX(tbl,,15),isCty,country=cty,isCat,IF(cat="",1,pcat=cat),isRisk,IF(maxRisk="LOW",risk="LOW",IF(maxRisk="MED",(risk="LOW")+(risk="MED"),1)),mask,(co<>"")*(em<>"")*isCty*isCat*isRisk,FILTER(HSTACK(sid,co,country,stype,pcat,scat,web,em,risk,ev),mask,"")) | J5: IV Cannulas | K5: HIGH
J6: IV Infusion Sets
J7: Catheters
J8: Gloves
J9: PPE
J10: Gauze & Bandages
J11: Disinfectants
J12: Lab Consumables

Sheet View_France
A1: View: France (filter by category + risk)
J2: Categories | K2: RiskLevels
A3: Category (optional) | D3: Filtered suppliers | J3: Wound Care | K3: LOW
A4: Max Risk (LOW/MED/HIGH) | B4: MED | D4: Supplier_ID | E4: Company | F4: Country | G4: Supplier_Type | H4: Primary_Category | I4: Secondary_Categories | J4: Syringes & Needles | K4: MED | L4: Risk_Level | M4: Evidence_URL
D5: =LET(cty,"France",cat,$B$3,maxRisk,$B$4,tbl,Supplier_Intelligence!$A$2:$U$3001,sid,INDEX(tbl,,1),co,INDEX(tbl,,2),country,INDEX(tbl,,3),stype,INDEX(tbl,,4),pcat,INDEX(tbl,,5),scat,INDEX(tbl,,6),web,INDEX(tbl,,8),em,INDEX(tbl,,9),risk,INDEX(tbl,,18),ev,INDEX(tbl,,15),isCty,country=cty,isCat,IF(cat="",1,pcat=cat),isRisk,IF(maxRisk="LOW",risk="LOW",IF(maxRisk="MED",(risk="LOW")+(risk="MED"),1)),mask,(co<>"")*(em<>"")*isCty*isCat*isRisk,FILTER(HSTACK(sid,co,country,stype,pcat,scat,web,em,risk,ev),mask,"")) | J5: IV Cannulas | K5: HIGH
J6: IV Infusion Sets
J7: Catheters
J8: Gloves
J9: PPE
J10: Gauze & Bandages
J11: Disinfectants
J12: Lab Consumables

Sheet View_Italy
A1: View: Italy (filter by category + risk)
J2: Categories | K2: RiskLevels
A3: Category (optional) | D3: Filtered suppliers | J3: Wound Care | K3: LOW
A4: Max Risk (LOW/MED/HIGH) | B4: MED | D4: Supplier_ID | E4: Company | F4: Country | G4: Supplier_Type | H4: Primary_Category | I4: Secondary_Categories | J4: Syringes & Needles | K4: MED | L4: Risk_Level | M4: Evidence_URL
D5: =LET(cty,"Italy",cat,$B$3,maxRisk,$B$4,tbl,Supplier_Intelligence!$A$2:$U$3001,sid,INDEX(tbl,,1),co,INDEX(tbl,,2),country,INDEX(tbl,,3),stype,INDEX(tbl,,4),pcat,INDEX(tbl,,5),scat,INDEX(tbl,,6),web,INDEX(tbl,,8),em,INDEX(tbl,,9),risk,INDEX(tbl,,18),ev,INDEX(tbl,,15),isCty,country=cty,isCat,IF(cat="",1,pcat=cat),isRisk,IF(maxRisk="LOW",risk="LOW",IF(maxRisk="MED",(risk="LOW")+(risk="MED"),1)),mask,(co<>"")*(em<>"")*isCty*isCat*isRisk,FILTER(HSTACK(sid,co,country,stype,pcat,scat,web,em,risk,ev),mask,"")) | J5: IV Cannulas | K5: HIGH
J6: IV Infusion Sets
J7: Catheters
J8: Gloves
J9: PPE
J10: Gauze & Bandages
J11: Disinfectants
J12: Lab Consumables

Sheet View_Spain
A1: View: Spain (filter by category + risk)
J2: Categories | K2: RiskLevels
A3: Category (optional) | D3: Filtered suppliers | J3: Wound Care | K3: LOW
A4: Max Risk (LOW/MED/HIGH) | B4: MED | D4: Supplier_ID | E4: Company | F4: Country | G4: Supplier_Type | H4: Primary_Category | I4: Secondary_Categories | J4: Syringes & Needles | K4: MED | L4: Risk_Level | M4: Evidence_URL
D5: =LET(cty,"Spain",cat,$B$3,maxRisk,$B$4,tbl,Supplier_Intelligence!$A$2:$U$3001,sid,INDEX(tbl,,1),co,INDEX(tbl,,2),country,INDEX(tbl,,3),stype,INDEX(tbl,,4),pcat,INDEX(tbl,,5),scat,INDEX(tbl,,6),web,INDEX(tbl,,8),em,INDEX(tbl,,9),risk,INDEX(tbl,,18),ev,INDEX(tbl,,15),isCty,country=cty,isCat,IF(cat="",1,pcat=cat),isRisk,IF(maxRisk="LOW",risk="LOW",IF(maxRisk="MED",(risk="LOW")+(risk="MED"),1)),mask,(co<>"")*(em<>"")*isCty*isCat*isRisk,FILTER(HSTACK(sid,co,country,stype,pcat,scat,web,em,risk,ev),mask,"")) | J5: IV Cannulas | K5: HIGH
J6: IV Infusion Sets
J7: Catheters
J8: Gloves
J9: PPE
J10: Gauze & Bandages
J11: Disinfectants
J12: Lab Consumables

Sheet View_United_Kingdom
A1: View: United Kingdom (filter by category + risk)
J2: Categories | K2: RiskLevels
A3: Category (optional) | D3: Filtered suppliers | J3: Wound Care | K3: LOW
A4: Max Risk (LOW/MED/HIGH) | B4: MED | D4: Supplier_ID | E4: Company | F4: Country | G4: Supplier_Type | H4: Primary_Category | I4: Secondary_Categories | J4: Syringes & Needles | K4: MED | L4: Risk_Level | M4: Evidence_URL
D5: =LET(cty,"United Kingdom",cat,$B$3,maxRisk,$B$4,tbl,Supplier_Intelligence!$A$2:$U$3001,sid,INDEX(tbl,,1),co,INDEX(tbl,,2),country,INDEX(tbl,,3),stype,INDEX(tbl,,4),pcat,INDEX(tbl,,5),scat,INDEX(tbl,,6),web,INDEX(tbl,,8),em,INDEX(tbl,,9),risk,INDEX(tbl,,18),ev,INDEX(tbl,,15),isCty,country=cty,isCat,IF(cat="",1,pcat=cat),isRisk,IF(maxRisk="LOW",risk="LOW",IF(maxRisk="MED",(risk="LOW")+(risk="MED"),1)),mask,(co<>"")*(em<>"")*isCty*isCat*isRisk,FILTER(HSTACK(sid,co,country,stype,pcat,scat,web,em,risk,ev),mask,"")) | J5: IV Cannulas | K5: HIGH
J6: IV Infusion Sets
J7: Catheters
J8: Gloves
J9: PPE
J10: Gauze & Bandages
J11: Disinfectants
J12: Lab Consumables
